<?xml version="1.0" encoding="utf-8" ?>
<!-- =================================================================================== -->
<!-- |    This document was autogenerated by xacro from /home/linux/weldingbot_ws/src/motoman/motoman_gp12_support/urdf/gp12.xacro | -->
<!-- |    EDITING THIS FILE BY HAND IS NOT RECOMMENDED                                 | -->
<!-- =================================================================================== -->
<robot name="motoman_gp12">
    <!-- Properties -->
    <material name="yaskawa_blue">
        <color rgba="0.12941 0.14902 0.74902 1" />
    </material>
    <material name="yaskawa_black">
        <color rgba="0.8 0.8 0.8 1" />
    </material>
    <!-- link list -->
    <link name="base_link">
        <visual>
            <geometry>
                <mesh filename="package://motoman_gp12_support/meshes/visual/gp12_base_link.stl" />
            </geometry>
            <material name="yaskawa_blue" />
        </visual>
        <collision>
            <geometry>
                <mesh filename="package://motoman_gp12_support/meshes/collision/gp12_base_link.stl" />
            </geometry>
        </collision>
        
<inertial>
            <mass value="0.1" />
            <inertia ixx="0.03" iyy="0.03" izz="0.03" ixy="0.0" ixz="0.0" iyz="0.0" />
        </inertial>

    </link>
    <gazebo reference="base_link">
        <material>Gazebo/SkyBlue</material>
    </gazebo>
    <link name="link_1_s">
        <visual>
            <geometry>
                <mesh filename="package://motoman_gp12_support/meshes/visual/gp12_link_1_s.stl" />
            </geometry>
            <material name="yaskawa_blue" />
        </visual>
        <collision>
            <geometry>
                <mesh filename="package://motoman_gp12_support/meshes/collision/gp12_link_1_s.stl" />
            </geometry>
        </collision>
        
<inertial>
            <mass value="0.1" />
            <inertia ixx="0.03" iyy="0.03" izz="0.03" ixy="0.0" ixz="0.0" iyz="0.0" />
        </inertial>

    </link>
    <gazebo reference="link_1_s">
        <material>Gazebo/SkyBlue</material>
    </gazebo>
    <link name="link_2_l">
        <visual>
            <geometry>
                <mesh filename="package://motoman_gp12_support/meshes/visual/gp12_link_2_l.stl" />
            </geometry>
            <material name="yaskawa_blue" />
        </visual>
        <collision>
            <geometry>
                <mesh filename="package://motoman_gp12_support/meshes/collision/gp12_link_2_l.stl" />
            </geometry>
        </collision>
        
<inertial>
            <mass value="0.1" />
            <inertia ixx="0.03" iyy="0.03" izz="0.03" ixy="0.0" ixz="0.0" iyz="0.0" />
        </inertial>

    </link>
    <gazebo reference="link_2_l">
        <material>Gazebo/SkyBlue</material>
    </gazebo>
    <link name="link_3_u">
        <visual>
            <geometry>
                <mesh filename="package://motoman_gp12_support/meshes/visual/gp12_link_3_u.stl" />
            </geometry>
            <material name="yaskawa_blue" />
        </visual>
        <collision>
            <geometry>
                <mesh filename="package://motoman_gp12_support/meshes/collision/gp12_link_3_u.stl" />
            </geometry>
        </collision>
        
<inertial>
            <mass value="0.1" />
            <inertia ixx="0.03" iyy="0.03" izz="0.03" ixy="0.0" ixz="0.0" iyz="0.0" />
        </inertial>

    </link>
    <gazebo reference="link_3_u">
        <material>Gazebo/SkyBlue</material>
    </gazebo>
    <link name="link_4_r">
        <visual>
            <geometry>
                <mesh filename="package://motoman_gp12_support/meshes/visual/gp12_link_4_r.stl" />
            </geometry>
            <material name="yaskawa_blue" />
        </visual>
        <collision>
            <geometry>
                <mesh filename="package://motoman_gp12_support/meshes/collision/gp12_link_4_r.stl" />
            </geometry>
        </collision>
        
<inertial>
            <mass value="0.1" />
            <inertia ixx="0.03" iyy="0.03" izz="0.03" ixy="0.0" ixz="0.0" iyz="0.0" />
        </inertial>

    </link>
    <gazebo reference="link_4_r">
        <material>Gazebo/SkyBlue</material>
    </gazebo>
    <link name="link_5_b">
        <visual>
            <geometry>
                <mesh filename="package://motoman_gp12_support/meshes/visual/gp12_link_5_b.stl" />
            </geometry>
            <material name="yaskawa_blue" />
        </visual>
        <collision>
            <geometry>
                <mesh filename="package://motoman_gp12_support/meshes/collision/gp12_link_5_b.stl" />
            </geometry>
        </collision>
        
<inertial>
            <mass value="0.1" />
            <inertia ixx="0.03" iyy="0.03" izz="0.03" ixy="0.0" ixz="0.0" iyz="0.0" />
        </inertial>

    </link>
    <gazebo reference="link_5_b">
  <visual>
    <material>
      <ambient>0.0 0.3254902 0.8352941 1</ambient>
      <diffuse>0.0 0.3254902 0.8352941 1</diffuse>
      <specular>0.1 0.1 0.1 1</specular>
      <emissive>0 0 0 0</emissive>
    </material>
  </visual>
    </gazebo>
    <link name="link_6_t">
        <visual>
            <geometry>
                <mesh filename="package://motoman_gp12_support/meshes/visual/gp12_link_6_t.stl" />
            </geometry>
            <material name="yaskawa_blue" />
        </visual>
        <collision>
            <geometry>
                <mesh filename="package://motoman_gp12_support/meshes/collision/gp12_link_6_t.stl" />
            </geometry>
        </collision>
        
<inertial>
            <mass value="0.1" />
            <inertia ixx="0.03" iyy="0.03" izz="0.03" ixy="0.0" ixz="0.0" iyz="0.0" />
        </inertial>

    </link>
    <gazebo reference="link_6_t">
  <visual>
    <material>
      <ambient>0.0 0.3254902 0.8352941 1</ambient>
      <diffuse>0.0 0.3254902 0.8352941 1</diffuse>
      <specular>0.1 0.1 0.1 1</specular>
      <emissive>0 0 0 0</emissive>
    </material>
  </visual>
    </gazebo>
    <link name="tool0">
        <visual>
            <geometry>
                <mesh filename="package://motoman_gp12_support/meshes/visual/torch.stl" />
            </geometry>
            <material name="yaskawa_blue" />
        </visual>
        <collision>
            <geometry>
                <mesh filename="package://motoman_gp12_support/meshes/collision/torch.stl" />
            </geometry>
        </collision>
        
<inertial>
            <mass value="0.1" />
            <inertia ixx="0.03" iyy="0.03" izz="0.03" ixy="0.0" ixz="0.0" iyz="0.0" />
        </inertial>

    </link>
    <!-- end of link list -->
    <!-- joint list -->
    <joint name="joint_1_s" type="revolute">
        <parent link="base_link" />
        <child link="link_1_s" />
        <origin rpy="0 0 0" xyz="0 0 0.450" />
        <axis xyz="0 0 1" />
        <limit effort="926.10" lower="-2.9670" upper="2.9670" velocity="4.5355" />
    </joint>
    <joint name="joint_2_l" type="revolute">
        <parent link="link_1_s" />
        <child link="link_2_l" />
        <origin rpy="0 0 0" xyz="0.155 0 0" />
        <axis xyz="0 1 0" />
        <limit effort="1029.00" lower="-1.5708" upper="2.7052" velocity="4.0132" />
    </joint>
    <joint name="joint_3_u" type="revolute">
        <parent link="link_2_l" />
        <child link="link_3_u" />
        <origin rpy="0 0 0" xyz="0 0 0.614" />
        <axis xyz="0 -1 0" />
        <limit effort="551.25" lower="-1.4835" upper="2.6179" velocity="4.5375" />
    </joint>
    <joint name="joint_4_r" type="revolute">
        <parent link="link_3_u" />
        <child link="link_4_r" />
        <origin rpy="0 0 0" xyz="0.640 0 0.200" />
        <axis xyz="-1 0 0" />
        <limit effort="89.96" lower="-3.4906" upper="3.4906" velocity="8.2007" />
    </joint>
    <joint name="joint_5_b" type="revolute">
        <parent link="link_4_r" />
        <child link="link_5_b" />
        <origin rpy="0 0 0" xyz="0 0 0" />
        <axis xyz="0 -1 0" />
        <limit effort="67.03" lower="-2.6179" upper="2.6179" velocity="8.1992" />
    </joint>
    <joint name="joint_6_t" type="revolute">
        <parent link="link_5_b" />
        <child link="link_6_t" />
        <origin rpy="0 0 0" xyz="0 0 0" />
        <axis xyz="-1 0 0" />
        <limit effort="33.30" lower="-7.9412" upper="7.9412" velocity="12.2143" />
    </joint>
    <joint name="joint_6_t-tool0" type="fixed">
        <origin rpy="3.1415926 -1.570796 0" xyz="0.100 0 0" />
        <parent link="link_6_t" />
        <child link="tool0" />
    </joint>
    <!-- end of joint list -->
    <!-- ROS base_link to Robot Manufacturer World Coordinates transform -->
    <link name="world">
     <visual>
      <origin xyz=" 0 0 0"  rpy="0 0 0"/>
      <geometry>
               <box size="0.5 0.5 0.02" />
      </geometry>
      <material name="Brown" />
      </visual>

      <collision>
      <origin xyz=" 0 0 0"  rpy="0 0 0"/>
      <geometry>
               <box size="0.5 0.5 0.02" />
      </geometry>
      </collision>>

    </link>
    <joint name="base_link-base" type="fixed">
        <origin rpy="0 0 0" xyz="0 0 0.450" />
        <parent link="world" />
        <child link="base_link" />
    </joint>
    
    <transmission name="trans_joint_1_s">
        <type>transmission_interface/SimpleTransmission</type>
        <joint name="joint_1_s">
            <hardwareInterface>hardware_interface/PositionJointInterface</hardwareInterface>
        </joint>
        <actuator name="joint_1_s_motor">
            <hardwareInterface>hardware_interface/PositionJointInterface</hardwareInterface>
            <mechanicalReduction>1</mechanicalReduction>
        </actuator>
    </transmission>
    <transmission name="trans_joint_2_l">
        <type>transmission_interface/SimpleTransmission</type>
        <joint name="joint_2_l">
            <hardwareInterface>hardware_interface/PositionJointInterface</hardwareInterface>
        </joint>
        <actuator name="joint_2_l_motor">
            <hardwareInterface>hardware_interface/PositionJointInterface</hardwareInterface>
            <mechanicalReduction>1</mechanicalReduction>
        </actuator>
    </transmission>
    <transmission name="trans_joint_3_u">
        <type>transmission_interface/SimpleTransmission</type>
        <joint name="joint_3_u">
            <hardwareInterface>hardware_interface/PositionJointInterface</hardwareInterface>
        </joint>
        <actuator name="joint_3_u_motor">
            <hardwareInterface>hardware_interface/PositionJointInterface</hardwareInterface>
            <mechanicalReduction>1</mechanicalReduction>
        </actuator>
    </transmission>
    <transmission name="trans_joint_4_r">
        <type>transmission_interface/SimpleTransmission</type>
        <joint name="joint_4_r">
            <hardwareInterface>hardware_interface/PositionJointInterface</hardwareInterface>
        </joint>
        <actuator name="joint_4_r_motor">
            <hardwareInterface>hardware_interface/PositionJointInterface</hardwareInterface>
            <mechanicalReduction>1</mechanicalReduction>
        </actuator>
    </transmission>
    <transmission name="trans_joint_5_b">
        <type>transmission_interface/SimpleTransmission</type>
        <joint name="joint_5_b">
            <hardwareInterface>hardware_interface/PositionJointInterface</hardwareInterface>
        </joint>
        <actuator name="joint_5_b_motor">
            <hardwareInterface>hardware_interface/PositionJointInterface</hardwareInterface>
            <mechanicalReduction>1</mechanicalReduction>
        </actuator>
    </transmission>
    <transmission name="trans_joint_6_t">
        <type>transmission_interface/SimpleTransmission</type>
        <joint name="joint_6_t">
            <hardwareInterface>hardware_interface/PositionJointInterface</hardwareInterface>
        </joint>
        <actuator name="joint_6_t_motor">
            <hardwareInterface>hardware_interface/PositionJointInterface</hardwareInterface>
            <mechanicalReduction>1</mechanicalReduction>
        </actuator>
    </transmission>
    <gazebo>
        <plugin name="gazebo_ros_control" filename="libgazebo_ros_control.so">
            <robotNamespace>/</robotNamespace>
        </plugin>
    </gazebo>
</robot>
